Workbook
Name _2Excel_BuiltIn_Print_Area_1_1: #REF!
Name _2Excel_BuiltIn_Print_Area_1_1: #REF!
Name _2Excel_BuiltIn_Print_Area_1_1: #REF!
Name _h: NA()
Name Bappenas: #REF!
Name Bappenas: #REF!
Name Bappenas: #REF!
Name Excel_BuiltIn_Print_Area: #REF!
Name Excel_BuiltIn_Print_Area: #REF!
Name Excel_BuiltIn_Print_Area: #REF!
Name H: NA()
Name KATEGORI: [1]Sheet1!$A$2:$A$9
Name KATEGORI_2010: [1]Sheet1!$A$2:$A$55
Name KATEGORI_BESAR: [1]Sheet1!$R$2:$R$19
Name Nama_KabKota: [2]Sheet2!$F$2:$F$38
Name Nama_Provinsi: [2]Sheet2!$A$2:$A$35
Name NamaTabel: OFFSET(INDIRECT("S3R!$"&[2]S2LP!$G$2&"$6"),0,0,1,[2]S2LP!$G$1)
Name PRINT_AREA_MI: #REF!
Name PRINT_AREA_MI: #REF!
Name PRINT_AREA_MI: #REF!
Name PROVINSI_ADJ: [1]Sheet1!$E$2:$E$34
Name Tabel: OFFSET(INDIRECT("S3R!$"&[2]S2LP!$G$2&"$"&[2]S2LP!$H$1),0,0,1,[2]S2LP!$G$1)
Name TabelKab: OFFSET(INDIRECT("S3R!$"&[2]S2LP!$G$2&"$"&[2]S2LP!$H$2),0,0,1,[2]S2LP!$G$1)
Name TabelKabTotal: OFFSET(INDIRECT("S3R!$"&[2]S2LP!$G$2&"$170"),0,0,1,[2]S2LP!$G$1)
Name TabelTotal: OFFSET(INDIRECT("S3R!$"&[2]S2LP!$G$2&"$169"),0,0,1,[2]S2LP!$G$1)
Name Tahun: [2]Sheet1!$A$2:$A$18

Sheet maluku
A1: TABEL 1. PDRB SERI 2010 ATAS DASAR HARGA BERLAKU MENURUT LAPANGAN USAHA (JUTA RUPIAH)
A2: Propinsi | B2: : | C2: Maluku | D2: Kabupaten/Kota : | E2: Maluku
A4: Kategori | B4: Uraian | D4: 2008 | I4: =D4+1 -> 2009 | N4: =I4+1 -> 2010 | S4: =N4+1 -> 2011 | X4: =S4+1 -> 2012 | AC4: =X4+1 -> 2013 | AH4: =AC4+1 -> 2014 | AM4: =AH4+1 -> 2015 | AR4: =AM4+1 -> 2016 | AW4: =AR4+1 -> 2017 | BB4: =AW4+1 -> 2018 | BG4: =BB4+1 -> 2019 | BL4: =BG4+1 -> 2020 | BQ4: =BL4+1 -> 2021 | BV4: =BQ4+1 -> 2022 | CA4: =BV4+1 -> 2023 | CF4: =CA4+1 -> 2024 | CK4: =CF4+1 -> 2025
D5: Q1 | E5: Q2 | F5: Q3 | G5: Q4 | H5: Total | I5: Q1 | J5: Q2 | K5: Q3 | L5: Q4 | M5: Total | N5: Q1 | O5: Q2 | P5: Q3 | Q5: Q4 | R5: Total | S5: Q1 | T5: Q2 | U5: Q3 | V5: Q4 | W5: Total | X5: Q1 | Y5: Q2 | Z5: Q3 | AA5: Q4 | AB5: Total | AC5: Q1 | AD5: Q2 | AE5: Q3 | AF5: Q4 | AG5: Total | AH5: Q1 | AI5: Q2 | AJ5: Q3 | AK5: Q4 | AL5: Total | AM5: Q1 | AN5: Q2 | AO5: Q3 | AP5: Q4 | AQ5: Total | AR5: Q1 | AS5: Q2 | AT5: Q3 | AU5: Q4 | AV5: Total | AW5: Q1 | AX5: Q2 | AY5: Q3 | AZ5: Q4 | BA5: Total | BB5: Q1 | BC5: Q2 | BD5: Q3 | BE5: Q4 | BF5: Total | BG5: Q1 | BH5: Q2 | BI5: Q3 | BJ5: Q4 | BK5: Total | BL5: Q1 | BM5: Q2 | BN5: Q3 | BO5: Q4 | BP5: Total | BQ5: Q1 | BR5: Q2 | BS5: Q3 | BT5: Q4 | BU5: Total | BV5: Q1 | BW5: Q2 | BX5: Q3 | BY5: Q4 | BZ5: Total | CA5: Q1 | CB5: Q2 | CC5: Q3 | CD5: Q4 | CE5: Total | CF5: Q1 | CG5: Q2 | CH5: Q3 | CI5: Q4 | CJ5: Total | CK5: Q1 | CL5: Q2 | CM5: Q3 | CN5: Q4 | CO5: Total
A7: -1 | B7: -2 | D7: -3 | E7: =D7-1 -> -4 | F7: =E7-1 -> -5 | G7: =F7-1 -> -6 | H7: =G7-1 -> -7 | I7: =H7-1 -> -8 | J7: =I7-1 -> -9 | K7: =J7-1 -> -10 | L7: =K7-1 -> -11 | ... CO7: =CN7-1 -> -92
A9: A | B9: Pertanian, Kehutanan, dan Perikanan | D9: 958578.87 | E9: 990788.5 | F9: 992493.91 | G9: 1020263.5 | H9: 3962124.8 | I9: 1049032.3 | J9: 1074124.6 | K9: 1094601.1 | L9: 1163862.4 | M9: 4381620.4 | N9: 1158973 | O9: 1191615.8 | P9: 1223866 | Q9: 1251261.7 | R9: 4825716.6 | S9: 1296381.9 | T9: 1286608.5 | U9: 1343193 | V9: 1422446.3 | W9: 5348629.6 | X9: 1484545.9 | Y9: 1542341.1 | Z9: 1522527.4 | AA9: 1582567.2 | AB9: 6131981.7 | AC9: 1601726.9 | AD9: 1689611.5 | AE9: 1754217.2 | AF9: 1917132.1 | AG9: 6962687.7 | AH9: 1923812.4 | AI9: 1970794.3 | AJ9: 1988457.2 | AK9: 2026274.4 | AL9: 7909338.2 | AM9: 2048715.9 | AN9: 2068589.9 | AO9: 2063091.3 | AP9: 2096252.2 | AQ9: 8276649.4 | AR9: 2141907.8 | AS9: 2175266.4 | AT9: 2235560 | AU9: 2292052.7 | AV9: 8844787 | AW9: 2351780.3 | AX9: 2342467.5 | AY9: 2373551.4 | AZ9: 2424166.9 | BA9: 9491966.1 | BB9: 2433538.3 | BC9: 2449645.5 | BD9: 2525298.3 | BE9: 2636152.3 | BF9: 10044634 | BG9: 2618384.8 | BH9: 2630881.5 | BI9: 2730953.9 | BJ9: 2797203.4 | BK9: 10777424 | BL9: 2774360.8 | BM9: 2733236 | BN9: 2730011.4 | BO9: 2865452.9 | BP9: 11103061 | BQ9: 2759923.7 | BR9: 2766511.1 | BS9: 2823171.2 | BT9: 2931072.4 | BU9: 11280678 | BV9: 2997161.2 | BW9: 3053433 | BX9: 3261774.1 | BY9: 3338781 | BZ9: 12651149 | CA9: =CA10+CA18+CA19 -> 3360700.5 | CB9: =CB10+CB18+CB19 -> 3404414.9 | CC9: =CC10+CC18+CC19 -> 3530666.3 | CD9: =CD10+CD18+CD19 -> 3653918.3 | CE9: =CE10+CE18+CE19 -> 13949700 | CF9: =CF10+CF18+CF19 -> 3612643.6 | CG9: =CG10+CG18+CG19 -> 3569406.6 | CH9: =CH10+CH18+CH19 -> 3783473.5 | ... CO9: =CO10+CO18+CO19 -> 15887003
B10: 1 | C10: Pertanian, Peternakan, Perburuan dan Jasa Pertanian | D10: 446759.34 | E10: 459590.46 | F10: 460577.21 | G10: 472684.55 | H10: 1839611.6 | I10: 483366.61 | J10: 488500.83 | K10: 493362.16 | L10: 514743.29 | M10: 1979972.9 | N10: 515989.57 | O10: 526430.36 | P10: 542752.01 | Q10: 559472.46 | R10: 2144644.4 | S10: 573337.07 | T10: 578256.16 | U10: 600151.44 | V10: 627583.58 | W10: 2379328.3 | X10: 646743.44 | Y10: 664477.51 | Z10: 674749.63 | AA10: 700845 | AB10: 2686815.6 | AC10: 703021.09 | AD10: 735720.48 | AE10: 763426.38 | AF10: 821867.99 | AG10: 3024035.9 | AH10: 813695.17 | AI10: 839063.33 | AJ10: 852032.52 | AK10: 877174.06 | AL10: 3381965.1 | AM10: 884206.94 | AN10: 873412.84 | AO10: 874771.47 | AP10: 891391.04 | AQ10: 3523782.3 | AR10: 936223.92 | AS10: 952090.32 | AT10: 986589.68 | AU10: 1009300.5 | AV10: 3884204.4 | AW10: 1056783.5 | AX10: 1042781.8 | AY10: 1072230.1 | AZ10: 1066031.6 | BA10: 4237827.1 | BB10: 1073409.6 | BC10: 1089885.3 | BD10: 1130365.8 | BE10: 1159948.1 | BF10: 4453608.9 | BG10: 1153180.6 | BH10: 1159560.4 | BI10: 1213209.6 | BJ10: 1222974.1 | BK10: 4748924.7 | BL10: 1203855.3 | BM10: 1216487.5 | BN10: 1212755 | BO10: 1278298.1 | BP10: 4911396 | BQ10: 1174904.4 | BR10: 1179236.4 | BS10: 1191568.9 | BT10: 1263729.2 | BU10: 4809439 | BV10: 1284443.5 | BW10: 1304158.1 | BX10: 1330047.8 | BY10: 1300985.1 | BZ10: 5219634.5 | CA10: =SUM(CA11:CA17) -> 1352753.5 | CB10: =SUM(CB11:CB17) -> 1394479.1 | CC10: =SUM(CC11:CC17) -> 1418381.9 | CD10: =SUM(CD11:CD17) -> 1449265.8 | CE10: =SUM(CE11:CE17) -> 5614880.4 | CF10: =SUM(CF11:CF17) -> 1488477.3 | CG10: =SUM(CG11:CG17) -> 1535709.4 | CH10: =SUM(CH11:CH17) -> 1568468.6 | ... CO10: =SUM(CO11:CO17) -> 6380645.3
C11: a. Tanaman Pangan | D11: 251931.4 | E11: 260513.96 | F11: 256354.99 | G11: 264323.89 | H11: 1033124.2 | I11: 269530.4 | J11: 272268.64 | K11: 271801.45 | L11: 284761.81 | M11: 1098362.3 | N11: 289820.86 | O11: 295740.99 | P11: 302926.8 | Q11: 310003.18 | R11: 1198491.8 | S11: 316352.67 | T11: 316314.46 | U11: 332688.25 | V11: 346553.32 | W11: 1311908.7 | X11: 359786.78 | Y11: 367785.02 | Z11: 368500.42 | AA11: 379821.67 | AB11: 1475893.9 | AC11: 385175.92 | AD11: 400887.15 | AE11: 410585.31 | AF11: 438769.41 | AG11: 1635417.8 | AH11: 447493.01 | AI11: 460399.09 | AJ11: 467056.33 | AK11: 476066.75 | AL11: 1851015.2 | AM11: 492051.39 | AN11: 472676.27 | AO11: 464899.7 | AP11: 468269.48 | AQ11: 1897896.8 | AR11: 508390.88 | AS11: 511519.65 | AT11: 535295.36 | AU11: 553783.61 | AV11: 2108989.5 | AW11: 590904.11 | AX11: 558710.33 | AY11: 580758.84 | AZ11: 573854.53 | BA11: 2304227.8 | BB11: 574331.57 | BC11: 575476.74 | BD11: 596356.97 | BE11: 618534.07 | BF11: 2364699.3 | BG11: 608749.19 | BH11: 610204.28 | BI11: 642952.38 | BJ11: 636652.81 | BK11: 2498558.7 | BL11: 614563.83 | BM11: 628960.66 | BN11: 626449.76 | BO11: 684760.96 | BP11: 2554735.2 | BQ11: 573275.4 | BR11: 566766.1 | BS11: 566605.93 | BT11: 630849.88 | BU11: 2337497.3 | BV11: 639572.63 | BW11: 648111.79 | BX11: 650480.71 | BY11: 608221.13 | BZ11: 2546386.3 | CA11: 657214.75 | CB11: 675688.45 | CC11: 693211.95 | CD11: 684692.64 | CE11: =SUM(CA11:CD11) -> 2710807.8 | CF11: 718437.62 | CG11: 706253.69 | CH11: 775495.77 | CI11: 585772.41 | CJ11: =SUM(CF11:CI11) -> 2785959.5 | CK11: 751266.65 | CL11: 720465.91 | CM11: 817557.24 | CN11: 641604.29 | CO11: =SUM(CK11:CN11) -> 2930894.1
C12: b. Tanaman Hortikultura Semusim | D12: 25548.45 | E12: 26573.72 | F12: 26342.003 | G12: 26861.709 | H12: 105325.88 | I12: 27978.97 | J12: 28275.285 | K12: 28252.492 | L12: 29460.545 | M12: 113967.29 | N12: 30270.261 | O12: 30867.196 | P12: 32202.824 | Q12: 32921.572 | R12: 126261.85 | S12: 34066.652 | T12: 34053.957 | U12: 35479.034 | V12: 37638.55 | W12: 141238.19 | X12: 39217.983 | Y12: 40119.176 | Z12: 40199.64 | AA12: 41390.502 | AB12: 160927.3 | AC12: 42654.213 | AD12: 44392.245 | AE12: 45478.516 | AF12: 48520.072 | AG12: 181045.05 | AH12: 48939.28 | AI12: 49715.22 | AJ12: 50588.54 | AK12: 51854.77 | AL12: 201097.81 | AM12: 52706.27 | AN12: 53163.457 | AO12: 53456.374 | AP12: 54603.187 | AQ12: 213929.29 | AR12: 55759.804 | AS12: 56980.993 | AT12: 57680.065 | AU12: 59542.354 | AV12: 229963.22 | AW12: 60823.19 | AX12: 61691.457 | AY12: 62681.414 | AZ12: 63053.374 | BA12: 248249.44 | BB12: 64974.142 | BC12: 64941.805 | BD12: 66479.181 | BE12: 68905.743 | BF12: 265300.87 | BG12: 70966.109 | BH12: 70750.757 | BI12: 72342.242 | BJ12: 72674.604 | BK12: 286733.71 | BL12: 75604.177 | BM12: 76599.793 | BN12: 72835.687 | BO12: 74276.32 | BP12: 299315.98 | BQ12: 78306.603 | BR12: 80540.066 | BS12: 80948.832 | BT12: 81197.719 | BU12: 320993.22 | BV12: 87327.368 | BW12: 87408.179 | BX12: 90100.204 | BY12: 89966.806 | BZ12: 354802.56 | CA12: 92584.829 | CB12: 92840.298 | CC12: 96847.934 | CD12: 99626.189 | CE12: =SUM(CA12:CD12) -> 381899.25 | CF12: 100475.69 | CG12: 102249.21 | CH12: 104479.87 | CI12: 108671.01 | CJ12: =SUM(CF12:CI12) -> 415875.77 | CK12: 110314.94 | CL12: 114646.4 | CM12: 116352.48 | CN12: 116147.87 | CO12: =SUM(CK12:CN12) -> 457461.69
C13: c. Perkebunan Semusim | D13: 6129.2406 | E13: 6236.704 | F13: 6458.0731 | G13: 6567.6387 | H13: 25391.656 | I13: 6850.9688 | J13: 6918.7163 | K13: 7119.1361 | L13: 7339.3156 | M13: 28228.137 | N13: 7104.8959 | O13: 7269.909 | P13: 7557.1048 | Q13: 8147.2972 | R13: 30079.207 | S13: 8226.0996 | T13: 8359.8295 | U13: 8445.3653 | V13: 8848.4948 | W13: 33879.789 | X13: 9043.8196 | Y13: 9342.8523 | Z13: 9718.5599 | AA13: 10232.283 | AB13: 38337.514 | AC13: 10047.547 | AD13: 10603.293 | AE13: 11229.611 | AF13: 12226.427 | AG13: 44106.878 | AH13: 11520.23 | AI13: 11695.29 | AJ13: 11807.07 | AK13: 12478.55 | AL13: 47501.14 | AM13: 12218.629 | AN13: 12519.504 | AO13: 12643.685 | AP13: 12817.604 | AQ13: 50199.421 | AR13: 12891.875 | AS13: 12924.35 | AT13: 12992.623 | AU13: 13238.338 | AV13: 52047.186 | AW13: 13248.122 | AX13: 13269.162 | AY13: 13346.11 | AZ13: 13288.306 | BA13: 53151.7 | BB13: 13321.164 | BC13: 13380.974 | BD13: 13473.65 | BE13: 13604.637 | BF13: 53780.425 | BG13: 13653.104 | BH13: 13696.559 | BI13: 13715.874 | BJ13: 13744.781 | BK13: 54810.318 | BL13: 13882.938 | BM13: 13987.812 | BN13: 14015.063 | BO13: 14033.24 | BP13: 55919.053 | BQ13: 14090.424 | BR13: 14231.427 | BS13: 14303.985 | BT13: 14414.208 | BU13: 57040.043 | BV13: 14531.176 | BW13: 14687.189 | BX13: 14853.629 | BY13: 14862.664 | BZ13: 58934.658 | CA13: 14893.451 | CB13: 15033.272 | CC13: 14514.907 | CD13: 15991.229 | CE13: =SUM(CA13:CD13) -> 60432.858 | CF13: 14231.176 | CG13: 16233.867 | CH13: 16205.14 | CI13: 15882.618 | CJ13: =SUM(CF13:CI13) -> 62552.801 | CK13: 15924.468 | CL13: 16045.449 | CM13: 16317.055 | CN13: 15617.055 | CO13: =SUM(CK13:CN13) -> 63904.028
C14: d. Tanaman Hortikultura Tahunan dan Lainnya | D14: 250.23183 | E14: 264.64226 | F14: 262.55105 | G14: 268.17841 | H14: 1045.6036 | I14: 274.99865 | J14: 277.79791 | K14: 277.462 | L14: 289.4428 | M14: 1119.7014 | N14: 304.49201 | O14: 305.43592 | P14: 308.70407 | Q14: 310.83411 | R14: 1229.4661 | S14: 327.82109 | T14: 327.56312 | U14: 342.90113 | V14: 360.27698 | W14: 1358.5623 | X14: 382.12612 | Y14: 390.59342 | Z14: 391.53423 | AA14: 403.76478 | AB14: 1568.0185 | AC14: 417.85772 | AD14: 434.69967 | AE14: 445.51398 | AF14: 474.76579 | AG14: 1772.8372 | AH14: 477.17 | AI14: 484.13 | AJ14: 491.42 | AK14: 504.41 | AL14: 1957.13 | AM14: 516.30681 | AN14: 537.0026 | AO14: 537.86073 | AP14: 543.99389 | AQ14: 2135.164 | AR14: 559.13661 | AS14: 566.97415 | AT14: 563.24014 | AU14: 581.0504 | AV14: 2270.4013 | AW14: 603.04061 | AX14: 621.9233 | AY14: 627.89843 | AZ14: 634.60392 | BA14: 2487.4663 | BB14: 659.04194 | BC14: 672.37392 | BD14: 681.40593 | BE14: 689.90368 | BF14: 2702.7255 | BG14: 723.02 | BH14: 724.5 | BI14: 744.44548 | BJ14: 763.89939 | BK14: 2955.8649 | BL14: 790.5824 | BM14: 797.9322 | BN14: 758.60614 | BO14: 789.32 | BP14: 3136.4407 | BQ14: 810.30085 | BR14: 826.52094 | BS14: 831.43013 | BT14: 841.82878 | BU14: 3310.0807 | BV14: 870.44037 | BW14: 896.32365 | BX14: 920.76805 | BY14: 910.34016 | BZ14: 3597.8722 | CA14: 928.98683 | CB14: 952.46173 | CC14: 978.36047 | CD14: 998.94002 | CE14: =SUM(CA14:CD14) -> 3858.749 | CF14: 1018.6867 | CG14: 1048.7641 | CH14: 1071.7583 | CI14: 1105.575 | CJ14: =SUM(CF14:CI14) -> 4244.7841 | CK14: 1111.5802 | CL14: 1131.5575 | CM14: 1145.4612 | CN14: 1166.2589 | CO14: =SUM(CK14:CN14) -> 4554.8578
C15: e. Perkebunan Tahunan | D15: 133627.09 | E15: 135969.96 | F15: 140796.15 | G15: 143184.85 | H15: 553578.05 | I15: 147122.41 | J15: 148480.24 | K15: 152801.03 | L15: 157942.55 | M15: 606346.23 | N15: 154154.93 | O15: 156544.7 | P15: 162546.33 | Q15: 169749.7 | R15: 642995.66 | S15: 174666.68 | T15: 177506.2 | U15: 179322.4 | V15: 187882.15 | W15: 719377.43 | X15: 191148.05 | Y15: 197483.98 | Z15: 205370.89 | AA15: 216528.51 | AB15: 810531.44 | AC15: 213037.62 | AD15: 224931 | AE15: 238134.43 | AF15: 259758.63 | AG15: 935861.68 | AH15: 244166.74 | AI15: 253832.44 | AJ15: 258457.5 | AK15: 270718.27 | AL15: 1027174.9 | AM15: 261112.41 | AN15: 267990.09 | AO15: 275623.52 | AP15: 286107.09 | AQ15: 1090833.1 | AR15: 289777.38 | AS15: 300540.15 | AT15: 309443.12 | AU15: 310124.4 | AV15: 1209885.1 | AW15: 318520.46 | AX15: 333615.47 | AY15: 338950.31 | AZ15: 338529.47 | BA15: 1329615.7 | BB15: 343180.08 | BC15: 356013.62 | BD15: 372504.04 | BE15: 376015.5 | BF15: 1447713.2 | BG15: 377154.01 | BH15: 379788.89 | BI15: 396199.31 | BJ15: 409959.07 | BK15: 1563101.3 | BL15: 410776.35 | BM15: 410580.65 | BN15: 410662.98 | BO15: 415125.77 | BP15: 1647145.7 | BQ15: 419388.4 | BR15: 426063.59 | BS15: 434669.64 | BT15: 441729.57 | BU15: 1721851.2 | BV15: 445502.8 | BW15: 453442.74 | BX15: 469788.51 | BY15: 483677.4 | BZ15: 1852411.4 | CA15: 482230.23 | CB15: 501218.84 | CC15: 504179.42 | CD15: 535601.01 | CE15: =SUM(CA15:CD15) -> 2023229.5 | CF15: 542758.89 | CG15: 592907.98 | CH15: 555208.73 | CI15: 559526.96 | CJ15: =SUM(CF15:CI15) -> 2250402.6 | CK15: 592525.14 | CL15: 601065.48 | CM15: 621583.56 | CN15: 606959.07 | CO15: =SUM(CK15:CN15) -> 2422133.3
C16: f. Peternakan | D16: 20840.167 | E16: 21348.133 | F16: 21635.392 | G16: 22520.735 | H16: 86344.427 | I16: 22423.532 | J16: 22923.756 | K16: 23530.4 | L16: 24755.573 | M16: 93633.261 | N16: 24156.576 | O16: 25371.028 | P16: 26691.84 | Q16: 27647.579 | R16: 103867.02 | S16: 28527.8 | T16: 30530.579 | U16: 32308.189 | V16: 34069.621 | W16: 125436.19 | X16: 34570.036 | Y16: 36267.42 | Z16: 37583.435 | AA16: 38963.035 | AB16: 147383.93 | AC16: 38188.752 | AD16: 40213.567 | AE16: 42692.288 | AF16: 45861.607 | AG16: 166956.21 | AH16: 45090.42 | AI16: 46528.9 | AJ16: 47037.07 | AK16: 48518.22 | AL16: 187174.61 | AM16: 48601.001 | AN16: 48849.824 | AO16: 49730.64 | AP16: 50697.348 | AQ16: 197878.81 | AR16: 50262.951 | AS16: 50567.613 | AT16: 51104.03 | AU16: 52020.814 | AV16: 203955.41 | AW16: 52413.038 | AX16: 54386.013 | AY16: 54723.672 | AZ16: 55473.406 | BA16: 216996.13 | BB16: 55590.002 | BC16: 57907.453 | BD16: 59186.06 | BE16: 60230.111 | BF16: 232913.63 | BG16: 59920.501 | BH16: 62333.174 | BI16: 64685.293 | BJ16: 65965.44 | BK16: 252904.41 | BL16: 65001.972 | BM16: 62301.312 | BN16: 64658.184 | BO16: 65827.87 | BP16: 257789.34 | BQ16: 65510.415 | BR16: 66995.577 | BS16: 70160.523 | BT16: 69991.975 | BU16: 272658.49 | BV16: 71442.486 | BW16: 74194.248 | BX16: 77538.095 | BY16: 76943.129 | BZ16: 300117.96 | CA16: 77827.961 | CB16: 81304.151 | CC16: 81043.973 | CD16: 84337.558 | CE16: =SUM(CA16:CD16) -> 324513.64 | CF16: 83182.486 | CG16: 88442.486 | CH16: 86142.486 | CI16: 92363.78 | CJ16: =SUM(CF16:CI16) -> 350131.24 | CK16: 89781.3 | CL16: 95545.697 | CM16: 93301.183 | CN16: 99943.973 | CO16: =SUM(CK16:CN16) -> 378572.15
C17: g. Jasa Pertanian dan Perburuan | D17: 8432.7671 | E17: 8683.344 | F17: 8728.0506 | G17: 8957.5432 | H17: 34801.705 | I17: 9185.3367 | J17: 9356.3996 | K17: 9580.1995 | L17: 10194.052 | M17: 38315.987 | N17: 10177.561 | O17: 10331.105 | P17: 10518.398 | Q17: 10692.289 | R17: 41719.353 | S17: 11169.349 | T17: 11163.574 | U17: 11565.302 | V17: 12231.171 | W17: 46129.395 | X17: 12594.636 | Y17: 13088.467 | Z17: 12985.148 | AA17: 13505.236 | AB17: 52173.487 | AC17: 13499.178 | AD17: 14258.521 | AE17: 14860.716 | AF17: 16257.083 | AG17: 58875.497 | AH17: 16008.32 | AI17: 16408.26 | AJ17: 16594.59 | AK17: 17033.09 | AL17: 66044.26 | AM17: 17000.94 | AN17: 17676.691 | AO17: 17879.694 | AP17: 18352.329 | AQ17: 70909.653 | AR17: 18581.884 | AS17: 18990.585 | AT17: 19511.239 | AU17: 20009.943 | AV17: 77093.651 | AW17: 20271.579 | AX17: 20487.482 | AY17: 21141.895 | AZ17: 21197.942 | BA17: 83098.899 | BB17: 21353.564 | BC17: 21492.363 | BD17: 21684.54 | BE17: 21968.159 | BF17: 86498.627 | BG17: 22014.671 | BH17: 22062.205 | BI17: 22570.093 | BJ17: 23213.441 | BK17: 89860.41 | BL17: 23235.5 | BM17: 23259.352 | BN17: 23374.771 | BO17: 23484.651 | BP17: 93354.274 | BQ17: 23522.881 | BR17: 23813.133 | BS17: 24048.568 | BT17: 24704.029 | BU17: 96088.611 | BV17: 25196.578 | BW17: 25417.638 | BX17: 26365.885 | BY17: 26403.639 | BZ17: 103383.74 | CA17: 27073.339 | CB17: 27441.67 | CC17: 27605.364 | CD17: 28018.284 | CE17: =SUM(CA17:CD17) -> 110138.66 | CF17: 28372.738 | CG17: 28573.384 | CH17: 29864.807 | CI17: 30108.792 | CJ17: =SUM(CF17:CI17) -> 116919.72 | CK17: 30431.956 | CL17: 30166.64 | CM17: 30836.2 | CN17: 31690.423 | CO17: =SUM(CK17:CN17) -> 123125.22
B18: 2 | C18: Kehutanan dan Penebangan Kayu | D18: 26280.721 | E18: 25987.62 | F18: 27162.285 | G18: 27528.21 | H18: 106958.84 | I18: 26232.609 | J18: 27509.565 | K18: 27380.215 | L18: 27504.478 | M18: 108626.87 | N18: 26049.191 | O18: 27041.331 | P18: 28191.21 | Q18: 28956.063 | R18: 110237.79 | S18: 31209.888 | T18: 31985.969 | U18: 32848.969 | V18: 34907.559 | W18: 130952.39 | X18: 35046.184 | Y18: 36672.021 | Z18: 37119.243 | AA18: 37666.356 | AB18: 146503.8 | AC18: 34700.095 | AD18: 37936.906 | AE18: 41878.406 | AF18: 47132.637 | AG18: 161648.04 | AH18: 44958.26 | AI18: 46302.22 | AJ18: 47297.37 | AK18: 50724.69 | AL18: 189282.54 | AM18: 52199.485 | AN18: 49833.972 | AO18: 50694.228 | AP18: 54136.404 | AQ18: 206864.09 | AR18: 53791.001 | AS18: 50819.463 | AT18: 50838.688 | AU18: 54111.756 | AV18: 209560.91 | AW18: 54017.355 | AX18: 56727.768 | AY18: 56090.048 | AZ18: 58306.376 | BA18: 225141.55 | BB18: 58335.295 | BC18: 61104.135 | BD18: 61564.742 | BE18: 62974.207 | BF18: 243978.38 | BG18: 61301.115 | BH18: 61379.712 | BI18: 63681.42 | BJ18: 67335.392 | BK18: 253697.64 | BL18: 64632.237 | BM18: 61859.32 | BN18: 61007.822 | BO18: 63470.375 | BP18: 250969.75 | BQ18: 62342.497 | BR18: 59776.311 | BS18: 63692.242 | BT18: 71197.283 | BU18: 257008.33 | BV18: 69610.748 | BW18: 70804.291 | BX18: 74658.121 | BY18: 75524.433 | BZ18: 290597.59 | CA18: 70914.998 | CB18: 73238.895 | CC18: 69336.186 | CD18: 70691.922 | CE18: =SUM(CA18:CD18) -> 284182 | CF18: 69059.311 | CG18: 69569.726 | CH18: 71236.787 | CI18: 80747.746 | CJ18: =SUM(CF18:CI18) -> 290613.57 | CK18: 64071.152 | CL18: 73324.699 | CM18: 66091.738 | CN18: 75029.26 | CO18: =SUM(CK18:CN18) -> 278516.85
B19: 3 | C19: Perikanan | D19: 485538.81 | E19: 505210.42 | F19: 504754.42 | G19: 520050.72 | H19: 2015554.4 | I19: 539433.09 | J19: 558114.23 | K19: 573858.7 | L19: 621614.65 | M19: 2293020.7 | N19: 616934.28 | O19: 638144.15 | P19: 652922.82 | Q19: 662833.2 | R19: 2570834.4 | S19: 691834.92 | T19: 676366.35 | U19: 710192.59 | V19: 759955.13 | W19: 2838349 | X19: 802756.31 | Y19: 841191.61 | Z19: 810658.54 | AA19: 844055.82 | AB19: 3298662.3 | AC19: 864005.71 | AD19: 915954.1 | AE19: 948912.41 | AF19: 1048131.5 | AG19: 3777003.7 | AH19: 1065158.9 | AI19: 1085428.8 | AJ19: 1089127.3 | AK19: 1098375.6 | AL19: 4338090.6 | AM19: 1112309.5 | AN19: 1145343 | AO19: 1137625.7 | AP19: 1150724.8 | AQ19: 4546003 | AR19: 1151892.9 | AS19: 1172356.6 | AT19: 1198131.6 | AU19: 1228640.5 | AV19: 4751021.7 | AW19: 1240979.4 | AX19: 1242957.9 | AY19: 1245231.2 | AZ19: 1299828.9 | BA19: 5028997.4 | BB19: 1301793.5 | BC19: 1298656 | BD19: 1333367.7 | BE19: 1413230 | BF19: 5347047.2 | BG19: 1403903 | BH19: 1409941.4 | BI19: 1454062.8 | BJ19: 1506894 | BK19: 5774801.2 | BL19: 1505873.2 | BM19: 1454889.2 | BN19: 1456248.5 | BO19: 1523684.4 | BP19: 5940695.3 | BQ19: 1522676.8 | BR19: 1527498.4 | BS19: 1567910.1 | BT19: 1596145.9 | BU19: 6214231.2 | BV19: 1643107 | BW19: 1678470.6 | BX19: 1857068.2 | BY19: 1962271.5 | BZ19: 7140917.3 | CA19: 1937032 | CB19: 1936696.9 | CC19: 2042948.3 | CD19: 2133960.5 | CE19: =SUM(CA19:CD19) -> 8050637.7 | CF19: 2055107 | CG19: 1964127.5 | CH19: 2143768.2 | CI19: 2341768.2 | CJ19: =SUM(CF19:CI19) -> 8504770.9 | CK19: 2201527.4 | CL19: 2146126.6 | CM19: 2340413.1 | CN19: 2539773.3 | CO19: =SUM(CK19:CN19) -> 9227840.4
A20: B | B20: Pertambangan dan Penggalian | D20: 238217.29 | E20: 235861.59 | F20: 233755.81 | G20: 321494.38 | H20: 1029329.1 | I20: 134291.99 | J20: 127660.42 | K20: 133867 | L20: 136681.86 | M20: 532501.27 | N20: 137456.46 | O20: 143373.83 | P20: 152486.8 | Q20: 146188.58 | R20: 579505.67 | S20: 200662.9 | T20: 210575.33 | U20: 226663.94 | V20: 231773.91 | W20: 869676.07 | X20: 223585.68 | Y20: 235810.33 | Z20: 248666.29 | AA20: 267155.99 | AB20: 975218.3 | AC20: 223322.04 | AD20: 244500.37 | AE20: 267780.03 | AF20: 292784.09 | AG20: 1028386.5 | AH20: 317513.91 | AI20: 337471.8 | AJ20: 343350 | AK20: 271088.64 | AL20: 1269424.3 | AM20: 206026.73 | AN20: 228992.98 | AO20: 210759.84 | AP20: 191377.21 | AQ20: 837156.77 | AR20: 153190.9 | AS20: 184820.81 | AT20: 192303.59 | AU20: 223275.36 | AV20: 753590.66 | AW20: 234332.65 | AX20: 221434.04 | AY20: 219276.86 | AZ20: 237788.51 | BA20: 912832.06 | BB20: 251469.63 | BC20: 280166.23 | BD20: 293754.44 | BE20: 277975.81 | BF20: 1103366.1 | BG20: 256046.36 | BH20: 261915.13 | BI20: 257755.12 | BJ20: 279600.28 | BK20: 1055316.9 | BL20: 250982.29 | BM20: 232108.53 | BN20: 271051.9 | BO20: 261891.45 | BP20: 1016034.2 | BQ20: 273017.17 | BR20: 286916.78 | BS20: 299511 | BT20: 317548.82 | BU20: 1176993.8 | BV20: 359642.85 | BW20: 415511.35 | BX20: 356006.68 | BY20: 278501.51 | BZ20: 1409662.4 | CA20: =SUM(CA21:CA24) -> 248915.19 | CB20: =SUM(CB21:CB24) -> 249428.87 | CC20: =SUM(CC21:CC24) -> 290238.64 | CD20: =SUM(CD21:CD24) -> 293165.57 | CE20: =SUM(CE21:CE24) -> 1081748.3 | CF20: =SUM(CF21:CF24) -> 264170.73 | CG20: =SUM(CG21:CG24) -> 302482.01 | CH20: =SUM(CH21:CH24) -> 261600.7 | ... CO20: =SUM(CO21:CO24) -> 960464.44
B21: 1 | C21: Pertambangan Minyak, Gas dan Panas Bumi | D21: 222488.04 | E21: 219085.77 | F21: 215737.02 | G21: 301273.96 | H21: 958584.79 | I21: 113362.43 | J21: 106432.96 | K21: 110211.03 | L21: 111187.13 | M21: 441193.54 | N21: 112023.51 | O21: 114909.71 | P21: 122475.74 | Q21: 116068.48 | R21: 465477.44 | S21: 168946.09 | T21: 177416.56 | U21: 191705.57 | V21: 192926.46 | W21: 730994.69 | X21: 184661.24 | Y21: 195897.78 | Z21: 208568.83 | AA21: 225232.92 | AB21: 814360.78 | AC21: 185309.12 | AD21: 202414.57 | AE21: 220787.43 | AF21: 240716.66 | AG21: 849227.78 | AH21: 245997.36 | AI21: 267830.57 | AJ21: 271753.29 | AK21: 198072.66 | AL21: 983653.89 | AM21: 145447.96 | AN21: 163265.19 | AO21: 143573.96 | AP21: 122886.71 | AQ21: 575173.81 | AR21: 87465.261 | AS21: 117250.95 | AT21: 122780.17 | AU21: 151009.23 | AV21: 478505.61 | AW21: 164300.44 | AX21: 148791.62 | AY21: 143701.62 | AZ21: 159304.49 | BA21: 616098.17 | BB21: 175420.6 | BC21: 201609.46 | BD21: 211818.08 | BE21: 195507.31 | BF21: 784355.46 | BG21: 175322.83 | BH21: 178382.64 | BI21: 170871.55 | BJ21: 188107.11 | BK21: 712684.13 | BL21: 165436.71 | BM21: 146011.92 | BN21: 184661.31 | BO21: 173674.46 | BP21: 669784.39 | BQ21: 186874.9 | BR21: 194210.65 | BS21: 205408.91 | BT21: 220614.84 | BU21: 807109.3 | BV21: 266648.28 | BW21: 316523.36 | BX21: 255512.98 | BY21: 171026.8 | BZ21: 1009711.4 | CA21: 143713.78 | CB21: 141157.29 | CC21: 177292.52 | CD21: 178853.62 | CE21: =SUM(CA21:CD21) -> 641017.21 | CF21: 152912.08 | CG21: 167938.51 | CH21: 145883.54 | CI21: 106471.93 | CJ21: =SUM(CF21:CI21) -> 573206.06 | CK21: 125987.91 | CL21: 101875.15 | CM21: 105430.25 | CN21: 87762.138 | CO21: =SUM(CK21:CN21) -> 421055.45
B22: 2 | C22: Pertambangan Batubara dan Lignit | D22: 0 | E22: 0 | F22: 0 | G22: 0 | H22: 0 | I22: 0 | J22: 0 | K22: 0 | L22: 0 | M22: 0 | N22: 0 | O22: 0 | P22: 0 | Q22: 0 | R22: 0 | S22: 0 | T22: 0 | U22: 0 | V22: 0 | W22: 0 | X22: 0 | Y22: 0 | Z22: 0 | AA22: 0 | AB22: 0 | AC22: 0 | AD22: 0 | AE22: 0 | AF22: 0 | AG22: 0 | AH22: 0 | AI22: 0 | AJ22: 0 | AK22: 0 | AL22: 0 | AM22: 0 | AN22: 0 | AO22: 0 | AP22: 0 | AQ22: 0 | AR22: 0 | AS22: 0 | AT22: 0 | AU22: 0 | AV22: 0 | AW22: 0 | AX22: 0 | AY22: 0 | AZ22: 0 | BA22: 0 | BB22: 0 | BC22: 0 | BD22: 0 | BE22: 0 | BF22: 0 | BG22: 0 | BH22: 0 | BI22: 0 | BJ22: 0 | BK22: 0 | BL22: 0 | BM22: 0 | BN22: 0 | BO22: 0 | BP22: 0 | BQ22: 0 | BR22: 0 | BS22: 0 | BT22: 0 | BU22: 0 | BV22: 0 | BW22: 0 | BX22: 0 | BY22: 0 | BZ22: 0 | CA22: 0 | CB22: 0 | CC22: 0 | CD22: 0 | CE22: =SUM(CA22:CD22) -> 0 | CF22: 0 | CG22: 0 | CH22: 0 | CI22: 0 | CJ22: =SUM(CF22:CI22) -> 0 | CK22: 0 | CL22: 0 | CM22: 0 | CN22: 0 | CO22: =SUM(CK22:CN22) -> 0
B23: 3 | C23: Pertambangan Bijih Logam | D23: 0 | E23: 0 | F23: 0 | G23: 0 | H23: 0 | I23: 0 | J23: 0 | K23: 0 | L23: 0 | M23: 0 | N23: 0 | O23: 0 | P23: 0 | Q23: 0 | R23: 0 | S23: 793.42194 | T23: 857.69691 | U23: 974.01218 | V23: 1578.679 | W23: 4203.81 | X23: 1845.3422 | Y23: 1110.4338 | Z23: 1062.6494 | AA23: 906.78463 | AB23: 4925.21 | AC23: 404.61657 | AD23: 951.40779 | AE23: 976.7861 | AF23: 941.40954 | AG23: 3274.22 | AH23: 20713.82 | AI23: 17405.712 | AJ23: 17044.402 | AK23: 16127.776 | AL23: 71291.709 | AM23: 5161.3325 | AN23: 5254.8414 | AO23: 5345.043 | AP23: 5268.3138 | AQ23: 21029.531 | AR23: 5223.1358 | AS23: 5353.2692 | AT23: 5670.7415 | AU23: 5830.5779 | AV23: 22077.724 | AW23: 5942.5419 | AX23: 6090.0015 | AY23: 6262.2982 | AZ23: 6453.9105 | BA23: 24748.752 | BB23: 6471.1043 | BC23: 6477.7882 | BD23: 6505.872 | BE23: 6643.1062 | BF23: 26097.871 | BG23: 6781.5045 | BH23: 6822.8465 | BI23: 7198.6744 | BJ23: 7408.5333 | BK23: 28211.559 | BL23: 7422.2028 | BM23: 7445.6884 | BN23: 6965.2188 | BO23: 6782.2592 | BP23: 28615.369 | BQ23: 7045.6557 | BR23: 7583.2009 | BS23: 7627.3823 | BT23: 7738.9471 | BU23: 29995.186 | BV23: 7802.3099 | BW23: 8487.0456 | BX23: 8681.4416 | BY23: 8817.0977 | BZ23: 33787.895 | CA23: 9053.3307 | CB23: 9674.9732 | CC23: 9708.4388 | CD23: 9780.6836 | CE23: =SUM(CA23:CD23) -> 38217.426 | CF23: 9370.5943 | CG23: 29120.518 | CH23: 10128.078 | CI23: 8605.0313 | CJ23: =SUM(CF23:CI23) -> 57224.221 | CK23: 4326.634 | CL23: 7187.6741 | CM23: 44803.016 | CN23: 48912.526 | CO23: =SUM(CK23:CN23) -> 105229.85
B24: 4 | C24: Pertambangan dan Penggalian Lainnya | D24: 15729.251 | E24: 16775.825 | F24: 18018.788 | G24: 20220.422 | H24: 70744.286 | I24: 20929.562 | J24: 21227.458 | K24: 23655.966 | L24: 25494.735 | M24: 91307.721 | N24: 25432.946 | O24: 28464.12 | P24: 30011.064 | Q24: 30120.094 | R24: 114028.22 | S24: 30923.381 | T24: 32301.065 | U24: 33984.354 | V24: 37268.774 | W24: 134477.57 | X24: 37079.103 | Y24: 38802.116 | Z24: 39034.809 | AA24: 41016.284 | AB24: 155932.31 | AC24: 37608.305 | AD24: 41134.394 | AE24: 46015.813 | AF24: 51126.021 | AG24: 175884.53 | AH24: 50802.73 | AI24: 52235.51 | AJ24: 54552.3 | AK24: 56888.2 | AL24: 214478.74 | AM24: 55417.44 | AN24: 60472.953 | AO24: 61840.836 | AP24: 63222.191 | AQ24: 240953.42 | AR24: 60502.501 | AS24: 62216.593 | AT24: 63852.679 | AU24: 66435.552 | AV24: 253007.32 | AW24: 64089.661 | AX24: 66552.423 | AY24: 69312.934 | AZ24: 72030.115 | BA24: 271985.13 | BB24: 69577.93 | BC24: 72078.977 | BD24: 75430.486 | BE24: 75825.392 | BF24: 292912.79 | BG24: 73942.03 | BH24: 76709.638 | BI24: 79684.904 | BJ24: 84084.638 | BK24: 314421.21 | BL24: 78123.371 | BM24: 78650.92 | BN24: 79425.377 | BO24: 81434.739 | BP24: 317634.41 | BQ24: 79096.608 | BR24: 85122.927 | BS24: 86474.706 | BT24: 89195.029 | BU24: 339889.27 | BV24: 85192.258 | BW24: 90500.94 | BX24: 91812.256 | BY24: 98657.621 | BZ24: 366163.08 | CA24: 96148.073 | CB24: 98596.602 | CC24: 103237.67 | CD24: 104531.27 | CE24: =SUM(CA24:CD24) -> 402513.62 | CF24: 101888.06 | CG24: 105422.99 | CH24: 105589.08 | CI24: 108094.19 | CJ24: =SUM(CF24:CI24) -> 420994.32 | CK24: 103929.92 | CL24: 105201.89 | CM24: 110619.67 | CN24: 114427.67 | CO24: =SUM(CK24:CN24) -> 434179.15
A25: C | B25: Industri Pengolahan | D25: 179809.22 | E25: 199624.12 | F25: 218289.69 | G25: 225747.47 | H25: 823470.5 | I25: 219388.76 | J25: 222607 | K25: 228012.47 | L25: 242958.72 | M25: 912966.95 | N25: 241691.26 | O25: 241276.23 | P25: 254901.31 | Q25: 273160.66 | R25: 1011029.5 | S25: 270683.63 | T25: 287670.66 | U25: 285538.37 | V25: 306758.43 | W25: 1150651.1 | X25: 312024.08 | Y25: 334557.95 | Z25: 332898.22 | AA25: 335379 | AB25: 1314859.3 | AC25: 338125.19 | AD25: 357340.36 | AE25: 372632.23 | AF25: 396647.93 | AG25: 1464745.7 | AH25: 394522.4 | AI25: 399191.94 | AJ25: 418386.16 | AK25: 431685.23 | AL25: 1643785.7 | AM25: 433919.27 | AN25: 444981.72 | AO25: 458750.2 | AP25: 484140.93 | AQ25: 1821792.1 | AR25: 488688.55 | AS25: 492010.17 | AT25: 500883.55 | AU25: 517611.21 | AV25: 1999193.5 | AW25: 519551.62 | AX25: 520595.01 | AY25: 532769.12 | AZ25: 552173.47 | BA25: 2125089.2 | BB25: 562744.71 | BC25: 576288.4 | BD25: 576068.61 | BE25: 587031.55 | BF25: 2302133.3 | BG25: 583375.72 | BH25: 589855.85 | BI25: 601600.27 | BJ25: 618423.16 | BK25: 2393255 | BL25: 613012.58 | BM25: 573398.49 | BN25: 587168.97 | BO25: 589882.85 | BP25: 2363462.9 | BQ25: 623668.02 | BR25: 644805.24 | BS25: 679551.24 | BT25: 711475.16 | BU25: 2659499.7 | BV25: 743237.25 | BW25: 766544.09 | BX25: 791430.74 | BY25: 791368.55 | BZ25: 3092580.6 | CA25: =SUM(CA26:CA41) -> 900281.91 | CB25: =SUM(CB26:CB41) -> 944777.56 | CC25: =SUM(CC26:CC41) -> 913313.95 | CD25: =SUM(CD26:CD41) -> 904427.96 | CE25: =SUM(CE26:CE41) -> 3662801.4 | CF25: =SUM(CF26:CF41) -> 975010.97 | CG25: =SUM(CG26:CG41) -> 855599.17 | CH25: =SUM(CH26:CH41) -> 1065196 | ... CO25: =SUM(CO26:CO41) -> 4318234.1
B26: 1 | C26: Industri Batubara dan Pengilangan Migas | D26: 0 | E26: 0 | F26: 0 | G26: 0 | H26: 0 | I26: 0 | J26: 0 | K26: 0 | L26: 0 | M26: 0 | N26: 0 | O26: 0 | P26: 0 | Q26: 0 | R26: 0 | S26: 0 | T26: 0 | U26: 0 | V26: 0 | W26: 0 | X26: 0 | Y26: 0 | Z26: 0 | AA26: 0 | AB26: 0 | AC26: 0 | AD26: 0 | AE26: 0 | AF26: 0 | AG26: 0 | AH26: 0 | AI26: 0 | AJ26: 0 | AK26: 0 | AL26: 0 | AM26: 0 | AN26: 0 | AO26: 0 | AP26: 0 | AQ26: 0 | AR26: 0 | AS26: 0 | AT26: 0 | AU26: 0 | AV26: 0 | AW26: 0 | AX26: 0 | AY26: 0 | AZ26: 0 | BA26: 0 | BB26: 0 | BC26: 0 | BD26: 0 | BE26: 0 | BF26: 0 | BG26: 0 | BH26: 0 | BI26: 0 | BJ26: 0 | BK26: 0 | BL26: 0 | BM26: 0 | BN26: 0 | BO26: 0 | BP26: 0 | BQ26: 0 | BR26: 0 | BS26: 0 | BT26: 0 | BU26: 0 | BV26: 0 | BW26: 0 | BX26: 0 | BY26: 0 | BZ26: 0 | CA26: 0 | CB26: 0 | CC26: 0 | CD26: 0 | CE26: =SUM(CA26:CD26) -> 0 | CF26: 0 | CG26: 0 | CH26: 0 | CI26: 0 | CJ26: =SUM(CF26:CI26) -> 0 | CK26: 0 | CL26: 0 | CM26: 0 | CN26: 0 | CO26: =SUM(CK26:CN26) -> 0
B27: 2 | C27: Industri Makanan dan Minuman | D27: 55954.18 | E27: 56638.259 | F27: 54738.447 | G27: 58499.377 | H27: 225830.26 | I27: 59465.833 | J27: 61494.551 | K27: 62941.643 | L27: 63203.255 | M27: 247105.28 | N27: 63507.731 | O27: 66372.513 | P27: 70770.94 | Q27: 73782.515 | R27: 274433.7 | S27: 76552.729 | T27: 76872.361 | U27: 80635.89 | V27: 84988.62 | W27: 319049.6 | X27: 82333.853 | Y27: 92307.987 | Z27: 94806.268 | AA27: 95935.117 | AB27: 365383.22 | AC27: 89559.67 | AD27: 103934.83 | AE27: 108291.16 | AF27: 114002.92 | AG27: 415788.58 | AH27: 112477.79 | AI27: 114556.57 | AJ27: 119121.53 | AK27: 124874.31 | AL27: 471030.2 | AM27: 124157.13 | AN27: 134835.49 | AO27: 141157.36 | AP27: 152309.42 | AQ27: 552459.39 | AR27: 143914.4 | AS27: 151401.12 | AT27: 159585.79 | AU27: 166392.46 | AV27: 621293.77 | AW27: 169306.83 | AX27: 168080.44 | AY27: 174955.14 | AZ27: 176468.12 | BA27: 688810.52 | BB27: 182131.64 | BC27: 182080.7 | BD27: 183544.03 | BE27: 191150.97 | BF27: 738907.35 | BG27: 190100.13 | BH27: 191939.77 | BI27: 194308.79 | BJ27: 196675.37 | BK27: 773024.07 | BL27: 193569.53 | BM27: 177499.12 | BN27: 188716.66 | BO27: 193630.07 | BP27: 753415.39 | BQ27: 194789.6 | BR27: 181726.04 | BS27: 192641.15 | BT27: 201064.72 | BU27: 770221.51 | BV27: 213206.81 | BW27: 224997.82 | BX27: 242015.85 | BY27: 257153.74 | BZ27: 937374.23 | CA27: 242282.4 | CB27: 249573.36 | CC27: 260478.09 | CD27: 264418.04 | CE27: =SUM(CA27:CD27) -> 1016751.9 | CF27: 268115.34 | CG27: 271700.31 | CH27: 272080.71 | CI27: 292518.75 | CJ27: =SUM(CF27:CI27) -> 1104415.1 | CK27: 293390.43 | CL27: 296296.7 | CM27: 322508.24 | CN27: 354233.57 | CO27: =SUM(CK27:CN27) -> 1266428.9
B28: 3 | C28: Pengolahan Tembakau | D28: 0 | E28: 0 | F28: 0 | G28: 0 | H28: 0 | I28: 0 | J28: 0 | K28: 0 | L28: 0 | M28: 0 | N28: 0 | O28: 0 | P28: 0 | Q28: 0 | R28: 0 | S28: 0 | T28: 0 | U28: 0 | V28: 0 | W28: 0 | X28: 0 | Y28: 0 | Z28: 0 | AA28: 0 | AB28: 0 | AC28: 0 | AD28: 0 | AE28: 0 | AF28: 0 | AG28: 0 | AH28: 0 | AI28: 0 | AJ28: 0 | AK28: 0 | AL28: 0 | AM28: 0 | AN28: 0 | AO28: 0 | AP28: 0 | AQ28: 0 | AR28: 0 | AS28: 0 | AT28: 0 | AU28: 0 | AV28: 0 | AW28: 0 | AX28: 0 | AY28: 0 | AZ28: 0 | BA28: 0 | BB28: 0 | BC28: 0 | BD28: 0 | BE28: 0 | BF28: 0 | BG28: 0 | BH28: 0 | BI28: 0 | BJ28: 0 | BK28: 0 | BL28: 0 | BM28: 0 | BN28: 0 | BO28: 0 | BP28: 0 | BQ28: 0 | BR28: 0 | BS28: 0 | BT28: 0 | BU28: 0 | BV28: 0 | BW28: 0 | BX28: 0 | BY28: 0 | BZ28: 0 | CA28: 0 | CB28: 0 | CC28: 0 | CD28: 0 | CE28: =SUM(CA28:CD28) -> 0 | CF28: 0 | CG28: 0 | CH28: 0 | CI28: 0 | CJ28: =SUM(CF28:CI28) -> 0 | CK28: 0 | CL28: 0 | CM28: 0 | CN28: 0 | CO28: =SUM(CK28:CN28) -> 0
B29: 4 | C29: Industri Tekstil dan Pakaian Jadi | D29: 915.90015 | E29: 981.44399 | F29: 1063.6467 | G29: 1095.057 | H29: 4056.0478 | I29: 1101.0937 | J29: 1071.4841 | K29: 1078.7463 | L29: 1080.2093 | M29: 4331.5333 | N29: 1088.3288 | O29: 1057.9833 | P29: 1141.5908 | Q29: 1160.6268 | R29: 4448.5297 | S29: 1159.8456 | T29: 1225.0891 | U29: 1227.2934 | V29: 1237.1141 | W29: 4849.3422 | X29: 1191.9793 | Y29: 1301.5992 | Z29: 1438.2044 | AA29: 1548.9437 | AB29: 5480.7265 | AC29: 1386.584 | AD29: 1491.3434 | AE29: 1562.154 | AF29: 1657.2269 | AG29: 6097.3083 | AH29: 1672.87 | AI29: 1692.16 | AJ29: 1729.08 | AK29: 1784.68 | AL29: 6878.79 | AM29: 1751.02 | AN29: 1756.0697 | AO29: 1815.0487 | AP29: 1893.821 | AQ29: 7215.9595 | AR29: 1804.9062 | AS29: 1890.4722 | AT29: 1913.6785 | AU29: 2116.5187 | AV29: 7725.5754 | AW29: 2008.8691 | AX29: 1990.7175 | AY29: 1939.9256 | AZ29: 2158.2544 | BA29: 8097.7666 | BB29: 2186.0274 | BC29: 2185.425 | BD29: 2256.8402 | BE29: 2455.5959 | BF29: 9083.8885 | BG29: 2363.8963 | BH29: 2451.4041 | BI29: 2393.5715 | BJ29: 2561.2321 | BK29: 9770.1039 | BL29: 2487.1143 | BM29: 2476.2461 | BN29: 2495.5365 | BO29: 2508.6071 | BP29: 9967.5041 | BQ29: 2506.9684 | BR29: 2498.3016 | BS29: 2487.7772 | BT29: 2713.3935 | BU29: 10206.441 | BV29: 2694.9538 | BW29: 2717.2241 | BX29: 2807.277 | BY29: 2791.9678 | BZ29: 11011.423 | CA29: 2794.1522 | CB29: 3009.0145 | CC29: 3130.7122 | CD29: 3166.5442 | CE29: =SUM(CA29:CD29) -> 12100.423 | CF29: 3187.0103 | CG29: 3236.2794 | CH29: 3567.8948 | CI29: 3604.6573 | CJ29: =SUM(CF29:CI29) -> 13595.842 | CK29: 3618.7947 | CL29: 3783.024 | CM29: 3765.5497 | CN29: 3834.0508 | CO29: =SUM(CK29:CN29) -> 15001.419
B30: 5 | C30: Industri Kulit, Barang dari Kulit dan Alas Kaki | D30: 0 | E30: 0 | F30: 0 | G30: 0 | H30: 0 | I30: 0 | J30: 0 | K30: 0 | L30: 0 | M30: 0 | N30: 0 | O30: 0 | P30: 0 | Q30: 0 | R30: 0 | S30: 0 | T30: 0 | U30: 0 | V30: 0 | W30: 0 | X30: 0 | Y30: 0 | Z30: 0 | AA30: 0 | AB30: 0 | AC30: 0 | AD30: 0 | AE30: 0 | AF30: 0 | AG30: 0 | AH30: 0 | AI30: 0 | AJ30: 0 | AK30: 0 | AL30: 0 | AM30: 0 | AN30: 0 | AO30: 0 | AP30: 0 | AQ30: 0 | AR30: 0 | AS30: 0 | AT30: 0 | AU30: 0 | AV30: 0 | AW30: 0 | AX30: 0 | AY30: 0 | AZ30: 0 | BA30: 0 | BB30: 0 | BC30: 0 | BD30: 0 | BE30: 0 | BF30: 0 | BG30: 0 | BH30: 0 | BI30: 0 | BJ30: 0 | BK30: 0 | BL30: 0 | BM30: 0 | BN30: 0 | BO30: 0 | BP30: 0 | BQ30: 0 | BR30: 0 | BS30: 0 | BT30: 0 | BU30: 0 | BV30: 0 | BW30: 0 | BX30: 0 | BY30: 0 | BZ30: 0 | CA30: 0 | CB30: 0 | CC30: 0 | CD30: 0 | CE30: =SUM(CA30:CD30) -> 0 | CF30: 0 | CG30: 0 | CH30: 0 | CI30: 0 | CJ30: =SUM(CF30:CI30) -> 0 | CK30: 0 | CL30: 0 | CM30: 0 | CN30: 0 | CO30: =SUM(CK30:CN30) -> 0
B31: 6 | C31: Industri Kayu, Barang dari Kayu dan Gabus dan Barang Anyaman dari Bambu, Rotan dan Sejenisnya | D31: 39125.25 | E31: 43770.224 | F31: 48189.231 | G31: 49913.375 | H31: 180998.08 | I31: 47224.128 | J31: 48186.045 | K31: 50007.327 | L31: 54837.015 | M31: 200254.51 | N31: 51753.441 | O31: 53455.008 | P31: 57431.555 | Q31: 61816.29 | R31: 224456.29 | S31: 59691.177 | T31: 62534.622 | U31: 62715.809 | V31: 73459.093 | W31: 258400.7 | X31: 70595.782 | Y31: 71502.842 | Z31: 78554.874 | AA31: 85510.073 | AB31: 306163.57 | AC31: 80331.069 | AD31: 88131.585 | AE31: 91246.413 | AF31: 98801.905 | AG31: 358510.97 | AH31: 98896.33 | AI31: 98440.89 | AJ31: 105055.33 | AK31: 107701.77 | AL31: 410094.32 | AM31: 111041.5 | AN31: 115683.03 | AO31: 120932.33 | AP31: 122726.7 | AQ31: 470383.56 | AR31: 123352.61 | AS31: 121129.45 | AT31: 120160.59 | AU31: 132480.44 | AV31: 497123.09 | AW31: 132701.26 | AX31: 134268.31 | AY31: 141089.66 | AZ31: 142225.02 | BA31: 550284.26 | BB31: 143814 | BC31: 149178.83 | BD31: 142279.38 | BE31: 156084.84 | BF31: 591357.06 | BG31: 152968.17 | BH31: 150253.83 | BI31: 154391.92 | BJ31: 166850 | BK31: 624463.92 | BL31: 164769.84 | BM31: 150117.27 | BN31: 147937.95 | BO31: 145872.23 | BP31: 608697.28 | BQ31: 145575.77 | BR31: 145073.51 | BS31: 154316.31 | BT31: 177094.24 | BU31: 622059.83 | BV31: 170517.62 | BW31: 176747.26 | BX31: 179685.2 | BY31: 185428.79 | BZ31: 712378.87 | CA31: 182026.78 | CB31: 183202.33 | CC31: 187341.57 | CD31: 178990.7 | CE31: =SUM(CA31:CD31) -> 731561.37 | CF31: 179531.74 | CG31: 180111.18 | CH31: 185950.25 | CI31: 196112 | CJ31: =SUM(CF31:CI31) -> 741705.17 | CK31: 181366.42 | CL31: 185816.74 | CM31: 183895.77 | CN31: 185145.09 | CO31: =SUM(CK31:CN31) -> 736224.02
B32: 7 | C32: Industri Kertas dan Barang dari Kertas, Percetakan dan Reproduksi Media Rekaman | D32: 318.48856 | E32: 330.26809 | F32: 336.89667 | G32: 339.56464 | H32: 1325.218 | I32: 358.03415 | J32: 361.65077 | K32: 373.1596 | L32: 364.25525 | M32: 1457.0998 | N32: 366.21888 | O32: 395.76435 | P32: 419.11113 | Q32: 437.51058 | R32: 1618.6049 | S32: 433.3529 | T32: 443.70701 | U32: 439.54915 | V32: 509.35669 | W32: 1825.9658 | X32: 500.6244 | Y32: 481.48173 | Z32: 507.38563 | AA32: 532.32304 | AB32: 2021.8148 | AC32: 564.45916 | AD32: 548.27969 | AE32: 529.7719 | AF32: 522.49578 | AG32: 2165.0065 | AH32: 559.75 | AI32: 560.12 | AJ32: 566.27 | AK32: 578.34 | AL32: 2264.48 | AM32: 612.46 | AN32: 644.73482 | AO32: 658.34905 | AP32: 665.5165 | AQ32: 2581.0604 | AR32: 652.51237 | AS32: 670.42172 | AT32: 712.70962 | AU32: 767.08574 | AV32: 2802.7294 | AW32: 714.47559 | AX32: 745.9221 | AY32: 822.16696 | AZ32: 827.26921 | BA32: 3109.8339 | BB32: 795.33117 | BC32: 865.21542 | BD32: 870.50829 | BE32: 874.77289 | BF32: 3405.8278 | BG32: 881.5438 | BH32: 934.1303 | BI32: 907.37672 | BJ32: 933.24227 | BK32: 3656.2931 | BL32: 891.19947 | BM32: 900.50119 | BN32: 978.31312 | BO32: 939.90311 | BP32: 3709.9169 | BQ32: 944.06582 | BR32: 943.82795 | BS32: 989.5024 | BT32: 1046.1936 | BU32: 3923.5897 | BV32: 1047.5266 | BW32: 1065.8823 | BX32: 1120.4059 | BY32: 1154.189 | BZ32: 4388.0039 | CA32: 1155.2684 | CB32: 1162.8994 | CC32: 1197.4133 | CD32: 1283.3813 | CE32: =SUM(CA32:CD32) -> 4798.9625 | CF32: 1290.2947 | CG32: 1298.1689 | CH32: 1315.2687 | CI32: 1435.6402 | CJ32: =SUM(CF32:CI32) -> 5339.3725 | CK32: 1383.9628 | CL32: 1416.1186 | CM32: 1451.87 | CN32: 1588.997 | CO32: =SUM(CK32:CN32) -> 5840.9484
B33: 8 | C33: Industri Kimia, Farmasi dan Obat Tradisional | D33: 134.17148 | E33: 149.95268 | F33: 170.77879 | G33: 160.67296 | H33: 615.57592 | I33: 172.42143 | J33: 173.16474 | K33: 166.02374 | L33: 183.74314 | M33: 695.35305 | N33: 185.7998 | O33: 195.47886 | P33: 192.04825 | Q33: 190.05074 | R33: 763.37766 | S33: 207.31077 | T33: 217.24695 | U33: 229.08598 | V33: 238.78319 | W33: 892.42689 | X33: 246.96054 | Y33: 260.42914 | Z33: 263.93392 | AA33: 284.15426 | AB33: 1055.4779 | AC33: 279.70788 | AD33: 289.93048 | AE33: 312.72462 | AF33: 352.43796 | AG33: 1234.8009 | AH33: 352.28 | AI33: 349.84 | AJ33: 360.27 | AK33: 363.22 | AL33: 1425.61 | AM33: 364.42 | AN33: 366.52282 | AO33: 366.24665 | AP33: 358.40403 | AQ33: 1455.5935 | AR33: 351.76537 | AS33: 368.93623 | AT33: 369.6754 | AU33: 394.85431 | AV33: 1485.2313 | AW33: 408.47419 | AX33: 390.47977 | AY33: 427.27057 | AZ33: 458.40738 | BA33: 1684.6319 | BB33: 459.34646 | BC33: 444.18784 | BD33: 443.28489 | BE33: 437.15999 | BF33: 1783.9792 | BG33: 464.05934 | BH33: 477.58076 | BI33: 487.92963 | BJ33: 467.10077 | BK33: 1896.6705 | BL33: 466.91962 | BM33: 467.71152 | BN33: 483.4222 | BO33: 506.65344 | BP33: 1924.7068 | BQ33: 550.6537 | BR33: 551.18804 | BS33: 572.98499 | BT33: 466.6549 | BU33: 2141.4816 | BV33: 512.30609 | BW33: 630.44242 | BX33: 705.66765 | BY33: 586.26523 | BZ33: 2434.6814 | CA33: 579.77524 | CB33: 590.50306 | CC33: 591.75031 | CD33: 594.75783 | CE33: =SUM(CA33:CD33) -> 2356.7864 | CF33: 597.06188 | CG33: 599.99283 | CH33: 606.70597 | CI33: 614.00066 | CJ33: =SUM(CF33:CI33) -> 2417.7613 | CK33: 614.43282 | CL33: 618.62126 | CM33: 624.26406 | CN33: 637.54303 | CO33: =SUM(CK33:CN33) -> 2494.8612
B34: 9 | C34: Industri Karet, Barang dari Karet dan Plastik | D34: 74591.044 | E34: 88109.303 | F34: 103210.66 | G34: 105763.09 | H34: 371674.1 | I34: 101326.37 | J34: 101054.5 | K34: 102503.54 | L34: 112214.54 | M34: 417098.96 | N34: 112693.47 | O34: 108565.56 | P34: 113696.92 | Q34: 125001.45 | R34: 459957.4 | S34: 121300.1 | T34: 134668.84 | U34: 127312.56 | V34: 132742.4 | W34: 516023.9 | X34: 144191.51 | Y34: 155064.91 | Z34: 143422.85 | AA34: 137321.6 | AB34: 580000.87 | AC34: 152456.87 | AD34: 148066.18 | AE34: 155051.5 | AF34: 164468.59 | AG34: 620043.13 | AH34: 164056.77 | AI34: 167030.12 | AJ34: 174909.43 | AK34: 179168.62 | AL34: 685164.94 | AM34: 178829.2 | AN34: 174090.51 | AO34: 175633.9 | AP34: 187512.21 | AQ34: 716065.83 | AR34: 199170.09 | AS34: 197406.68 | AT34: 198541.88 | AU34: 195713.63 | AV34: 790832.27 | AW34: 194304.49 | AX34: 194800.46 | AY34: 192883.33 | AZ34: 207647.48 | BA34: 789635.75 | BB34: 211151.8 | BC34: 219722.69 | BD34: 224734.17 | BE34: 215010.42 | BF34: 870619.09 | BG34: 215587.42 | BH34: 221988.29 | BI34: 227185.94 | BJ34: 229207.46 | BK34: 893969.1 | BL34: 229329.58 | BM34: 220425.64 | BN34: 224654.89 | BO34: 224844.72 | BP34: 899254.83 | BQ34: 225337.09 | BR34: 226331.21 | BS34: 227946.27 | BT34: 230927.14 | BU34: 910541.72 | BV34: 231204.14 | BW34: 241077.38 | BX34: 243846.72 | BY34: 245915.33 | BZ34: 962043.58 | CA34: 246819.12 | CB34: 245165.09 | CC34: 244910.8 | CD34: 248310.86 | CE34: =SUM(CA34:CD34) -> 985205.87 | CF34: 248670.03 | CG34: 248997.2 | CH34: 250648.41 | CI34: 257324.78 | CJ34: =SUM(CF34:CI34) -> 1005640.4 | CK34: 270244.56 | CL34: 282783.46 | CM34: 284408.19 | CN34: 287409.96 | CO34: =SUM(CK34:CN34) -> 1124846.2
B35: 10 | C35: Industri Barang Galian bukan Logam | D35: 1345.3317 | E35: 1199.8332 | F35: 1329.2977 | G35: 1248.8909 | H35: 5123.3535 | I35: 1460.8567 | J35: 1370.5306 | K35: 1340.5673 | L35: 1491.1515 | M35: 5663.1061 | N35: 1512.7026 | O35: 1550.2801 | P35: 1649.0932 | Q35: 1653.8121 | R35: 6365.888 | S35: 1909.4308 | T35: 1840.5291 | U35: 1764.7524 | V35: 1727.331 | W35: 7242.0434 | X35: 1911.4191 | Y35: 2060.3846 | Z35: 2139.9863 | AA35: 2180.126 | AB35: 8291.9161 | AC35: 2240.7099 | AD35: 2316.7522 | AE35: 2469.9215 | AF35: 2586.7089 | AG35: 9614.0925 | AH35: 2596.78 | AI35: 2509.45 | AJ35: 2624.35 | AK35: 2700.41 | AL35: 10430.99 | AM35: 2741.8 | AN35: 2877.1928 | AO35: 2887.7095 | AP35: 2848.9173 | AQ35: 11355.62 | AR35: 3009.8139 | AS35: 2958.2261 | AT35: 2969.6398 | AU35: 2896.887 | AV35: 11834.567 | AW35: 3129.8974 | AX35: 3209.8129 | AY35: 3175.7688 | AZ35: 3183.9719 | BA35: 12699.451 | BB35: 3338.3844 | BC35: 3464.9489 | BD35: 3432.9122 | BE35: 3439.1667 | BF35: 13675.412 | BG35: 3493.6206 | BH35: 3596.208 | BI35: 3704.6163 | BJ35: 4073.3415 | BK35: 14867.786 | BL35: 3749.2278 | BM35: 3740.476 | BN35: 3428.7383 | BO35: 3713.3 | BP35: 14631.742 | BQ35: 3738.2774 | BR35: 3755.1175 | BS35: 3785.3709 | BT35: 3955.7473 | BU35: 15234.513 | BV35: 3979.0347 | BW35: 4069.0305 | BX35: 4442.0833 | BY35: 4499.0313 | BZ35: 16989.18 | CA35: 4532.07 | CB35: 4620.21 | CC35: 4733.664 | CD35: 4806.7345 | CE35: =SUM(CA35:CD35) -> 18692.678 | CF35: 4823.4849 | CG35: 4842.5002 | CH35: 5049.2981 | CI35: 5330.5379 | CJ35: =SUM(CF35:CI35) -> 20045.821 | CK35: 5050.1369 | CL35: 5088.6412 | CM35: 6727.9785 | CN35: 6753.7178 | CO35: =SUM(CK35:CN35) -> 23620.474
B36: 11 | C36: Industri Logam Dasar | D36: 0 | E36: 0 | F36: 0 | G36: 0 | H36: 0 | I36: 0 | J36: 0 | K36: 0 | L36: 0 | M36: 0 | N36: 0 | O36: 0 | P36: 0 | Q36: 0 | R36: 0 | S36: 0 | T36: 0 | U36: 0 | V36: 0 | W36: 0 | X36: 0 | Y36: 0 | Z36: 0 | AA36: 0 | AB36: 0 | AC36: 0 | AD36: 0 | AE36: 0 | AF36: 0 | AG36: 0 | AH36: 64.43 | AI36: 65.23 | AJ36: 63.76 | AK36: 67.55 | AL36: 260.97 | AM36: 66.72 | AN36: 65.667226 | AO36: 68.827287 | AP36: 71.514781 | AQ36: 272.72929 | AR36: 74.386603 | AS36: 72.143818 | AT36: 75.417068 | AU36: 79.884074 | AV36: 301.83156 | AW36: 80.283702 | AX36: 80.833003 | AY36: 81.35889 | AZ36: 82.140536 | BA36: 324.61613 | BB36: 81.739243 | BC36: 82.630201 | BD36: 83.534185 | BE36: 84.066737 | BF36: 331.97037 | BG36: 84.314355 | BH36: 84.832057 | BI36: 85.196709 | BJ36: 86.231585 | BK36: 340.57471 | BL36: 86.362943 | BM36: 85.238504 | BN36: 85.56048 | BO36: 85.742566 | BP36: 342.90449 | BQ36: 32504.068 | BR36: 66199.714 | BS36: 78060.047 | BT36: 74945.634 | BU36: 251709.46 | BV36: 101300.64 | BW36: 95940.475 | BX36: 95619.897 | BY36: 72583.753 | BZ36: 365444.77 | CA36: 199140.43 | CB36: 236892.43 | CC36: 190144.34 | CD36: 181982.53 | CE36: =SUM(CA36:CD36) -> 808159.72 | CF36: 247959.56 | CG36: 123927.32 | CH36: 324357.83 | CI36: 275786.82 | CJ36: =SUM(CF36:CI36) -> 972031.52 | CK36: 265442.3 | CL36: 129703.65 | CM36: 304635.28 | CN36: 354966.78 | CO36: =SUM(CK36:CN36) -> 1054748
B37: 12 | C37: Industri Barang dari Logam, Komputer, Barang Elektronik, Optik dan Peralatan Listrik | D37: 42.083847 | E37: 42.782363 | F37: 45.874075 | G37: 42.803897 | H37: 173.54418 | I37: 44.251943 | J37: 45.408741 | K37: 48.270775 | L37: 48.298331 | M37: 186.22979 | N37: 46.806988 | O37: 47.420846 | P37: 52.819856 | Q37: 55.158204 | R37: 202.20589 | S37: 53.879629 | T37: 55.481833 | U37: 55.678499 | V37: 57.187992 | W37: 222.22795 | X37: 56.114883 | Y37: 59.033441 | Z37: 62.440111 | AA37: 67.246784 | AB37: 244.83522 | AC37: 67.303865 | AD37: 67.046627 | AE37: 66.882025 | AF37: 69.485523 | AG37: 270.71804 | AH37: 72.4 | AI37: 70.79 | AJ37: 70.98 | AK37: 73.48 | AL37: 287.65 | AM37: 72.26 | AN37: 71.255586 | AO37: 70.495961 | AP37: 68.601959 | AQ37: 282.61351 | AR37: 73.061108 | AS37: 72.238804 | AT37: 72.490626 | AU37: 71.84302 | AV37: 289.63356 | AW37: 70.204593 | AX37: 69.1927 | AY37: 66.737613 | AZ37: 69.175941 | BA37: 275.31085 | BB37: 69.29551 | BC37: 73.594648 | BD37: 75.570394 | BE37: 76.101845 | BF37: 294.5624 | BG37: 76.753259 | BH37: 75.270374 | BI37: 77.447584 | BJ37: 79.345564 | BK37: 308.81678 | BL37: 77.01437 | BM37: 77.238545 | BN37: 76.756227 | BO37: 78.153345 | BP37: 309.16249 | BQ37: 77.37738 | BR37: 77.620779 | BS37: 77.781888 | BT37: 92.763816 | BU37: 325.54386 | BV37: 87.137619 | BW37: 88.080193 | BX37: 89.176981 | BY37: 96.533459 | BZ37: 360.92825 | CA37: 96.567564 | CB37: 97.572554 | CC37: 97.628759 | CD37: 97.239113 | CE37: =SUM(CA37:CD37) -> 389.00799 | CF37: 97.290832 | CG37: 98.180454 | CH37: 98.995326 | CI37: 99.91 | CJ37: =SUM(CF37:CI37) -> 394.37661 | CK37: 99.799883 | CL37: 100.81499 | CM37: 101.03366 | CN37: 101.60449 | CO37: =SUM(CK37:CN37) -> 403.25303
... B41: 16 | C41: Industri pengolahan lainnya, jasa reparasi dan pemasangan mesin dan peralatan | D41: 752.14972 | E41: 770.81349 | F41: 788.54406 | G41: 799.1202 | H41: 3110.6275 | I41: 825.34127 | J41: 835.64214 | K41: 857.35155 | L41: 878.92876 | M41: 3397.2637 | N41: 942.94559 | O41: 987.44985 | P41: 1017.4119 | Q41: 785.68139 | R41: 3733.4887 | S41: 1096.6835 | T41: 1121.3034 | U41: 1048.1471 | V41: 878.50213 | W41: 4144.6362 | X41: 1189.4846 | Y41: 1139.9301 | Z41: 1173.5817 | AA41: 1100.8036 | AB41: 4603.8001 | AC41: 1163.0146 | AD41: 1213.6961 | AE41: 1308.8708 | AF41: 1438.0577 | AG41: 5123.6392 | AH41: 1373.65 | AI41: 1383.46 | AJ41: 1379.59 | AK41: 1563.01 | AL41: 5699.71 | AM41: 1509.7532 | AN41: 1625.5456 | AO41: 1747.451 | AP41: 1756.4718 | AQ41: 6639.2215 | AR41: 1777.6788 | AS41: 1783.6679 | AT41: 1760.7663 | AU41: 1744.9787 | AV41: 7067.0917 | AW41: 1720.2906 | AX41: 1752.0484 | AY41: 1846.2225 | AZ41: 2002.5351 | BA41: 7321.0967 | BB41: 2019.5606 | BC41: 2030.5075 | BD41: 2015.7143 | BE41: 2065.8668 | BF41: 8131.649 | BG41: 2063.1815 | BH41: 2163.0478 | BI41: 2162.5029 | BJ41: 2071.2036 | BK41: 8459.9359 | BL41: 2070.9106 | BM41: 2080.8632 | BN41: 2072.9064 | BO41: 2086.01 | BP41: 8310.6901 | BQ41: 2088.1736 | BR41: 2083.4571 | BS41: 2133.7422 | BT41: 2234.5382 | BU41: 8539.9111 | BV41: 2247.679 | BW41: 2327.8558 | BX41: 2363.1644 | BY41: 2380.8254 | BZ41: 9319.5245 | CA41: 2384.3711 | CB41: 2425.4131 | CC41: 2438.1108 | CD41: 2467.6864 | CE41: =SUM(CA41:CD41) -> 9715.5815 | CF41: 2467.0619 | CG41: 2500.3899 | CH41: 2557.6888 | CI41: 2587.2 | CJ41: =SUM(CF41:CI41) -> 10112.341 | CK41: 2624.5939 | CL41: 2622.7186 | CM41: 2747.0174 | CN41: 2831.2171 | CO41: =SUM(CK41:CN41) -> 10825.547
A42: D | B42: Pengadaan Listrik dan Gas | D42: 3609.4252 | E42: 3856.2706 | F42: 3962.6213 | G42: 3908.5293 | H42: 15336.846 | I42: 3244.4425 | J42: 3201.0459 | K42: 3083.9983 | L42: 2736.1146 | M42: 12265.601 | N42: 3649.9753 | O42: 3870.2158 | P42: 3721.7334 | Q42: 3882.4954 | R42: 15124.42 | S42: 3421.0036 | T42: 3570.2878 | U42: 3708.8687 | V42: 3894.3858 | W42: 14594.546 | X42: 3927.618 | Y42: 3889.1415 | Z42: 3802.1714 | AA42: 3888.3538 | AB42: 15507.285 | AC42: 3762.6716 | AD42: 3602.0882 | AE42: 3608.45 | AF42: 3807.3278 | AG42: 14780.538 | AH42: 4959.2303 | AI42: 5184.2571 | AJ42: 4955.2956 | AK42: 5830.4581 | AL42: 20929.241 | AM42: 9288.7048 | AN42: 5376.4734 | AO42: 5404.7317 | AP42: 7989.3332 | AQ42: 28059.243 | AR42: 8185.7661 | AS42: 8658.6193 | AT42: 8917.6142 | AU42: 9237.9558 | AV42: 34999.955 | AW42: 9609.3606 | AX42: 9443.8186 | AY42: 9181.1981 | AZ42: 9897.2067 | BA42: 38131.584 | BB42: 9754.0951 | BC42: 9888.2408 | BD42: 9894.2045 | BE42: 10835.272 | BF42: 40371.813 | BG42: 10663.304 | BH42: 10392.976 | BI42: 9244.0317 | BJ42: 10928.627 | BK42: 41228.939 | BL42: 11586.373 | BM42: 10730.406 | BN42: 10196.035 | BO42: 11564.679 | BP42: 44077.492 | BQ42: 11606.002 | BR42: 11957.793 | BS42: 11525.965 | BT42: 12454.509 | BU42: 47544.268 | BV42: 12577.293 | BW42: 12579.963 | BX42: 12174.23 | BY42: 13603.281 | BZ42: 50934.766 | CA42: =SUM(CA43:CA44) -> 13673.56 | CB42: =SUM(CB43:CB44) -> 14308.55 | CC42: =SUM(CC43:CC44) -> 13996.191 | CD42: =SUM(CD43:CD44) -> 14374.439 | CE42: =SUM(CE43:CE44) -> 56352.74 | CF42: =SUM(CF43:CF44) -> 14548.234 | CG42: =SUM(CG43:CG44) -> 15350.139 | CH42: =SUM(CH43:CH44) -> 15027.817 | ... CO42: =SUM(CO43:CO44) -> 63150.739
B43: 1 | C43: Ketenagalistrikan | D43: 3583.5386 | E43: 3828.143 | F43: 3931.0876 | G43: 3874.2033 | H43: 15216.972 | I43: 3210.3943 | J43: 3166.4808 | K43: 3050.8329 | L43: 2704.3306 | M43: 12132.039 | N43: 3611.0606 | O43: 3833.2632 | P43: 3686.4536 | Q43: 3846.3207 | R43: 14977.098 | S43: 3383.1764 | T43: 3531.3674 | U43: 3668.7284 | V43: 3852.4388 | W43: 14435.711 | X43: 3886.0114 | Y43: 3846.285 | Z43: 3758.6146 | AA43: 3843.555 | AB43: 15334.466 | AC43: 3715.3743 | AD43: 3555.4903 | AE43: 3560.1339 | AF43: 3755.2413 | AG43: 14586.24 | AH43: 4906.2903 | AI43: 5129.5771 | AJ43: 4898.6056 | AK43: 5773.0981 | AL43: 20707.571 | AM43: 9231.4148 | AN43: 5318.8454 | AO43: 5347.5326 | AP43: 7929.757 | AQ43: 27827.55 | AR43: 8124.3554 | AS43: 8596.6123 | AT43: 8854.8458 | AU43: 9171.0497 | AV43: 34746.863 | AW43: 9542.2938 | AX43: 9376.6702 | AY43: 9115.4432 | AZ43: 9828.1216 | BA43: 37862.529 | BB43: 9685.3002 | BC43: 9820.0711 | BD43: 9825.3181 | BE43: 10763.291 | BF43: 40093.98 | BG43: 10591.797 | BH43: 10321.868 | BI43: 9172.5569 | BJ43: 10854.579 | BK43: 40940.801 | BL43: 11511.482 | BM43: 10656.948 | BN43: 10126.944 | BO43: 11493.1 | BP43: 43788.474 | BQ43: 11533.244 | BR43: 11884.754 | BS43: 11452.752 | BT43: 12375.973 | BU43: 47246.722 | BV43: 12497.053 | BW43: 12501.438 | BX43: 12095.518 | BY43: 13518.999 | BZ43: 50613.007 | CA43: 13587.153 | CB43: 14222.472 | CC43: 13910.385 | CD43: 14285.565 | CE43: =SUM(CA43:CD43) -> 56005.575 | CF43: 14459.126 | CG43: 15261.347 | CH43: 14937.945 | CI43: 15174.47 | CJ43: =SUM(CF43:CI43) -> 59832.888 | CK43: 14463.276 | CL43: 15412.861 | CM43: 15396.14 | CN43: 17495.058 | CO43: =SUM(CK43:CN43) -> 62767.335
B44: 2 | C44: Pengadaan Gas dan Produksi Es | D44: 25.886612 | E44: 28.127665 | F44: 31.533683 | G44: 34.325959 | H44: 119.87392 | I44: 34.048246 | J44: 34.565081 | K44: 33.165444 | L44: 31.783977 | M44: 133.56275 | N44: 38.914726 | O44: 36.952668 | P44: 35.279738 | Q44: 36.174666 | R44: 147.3218 | S44: 37.827196 | T44: 38.920356 | U44: 40.140322 | V44: 41.947025 | W44: 158.8349 | X44: 41.606639 | Y44: 42.856406 | Z44: 43.556794 | AA44: 44.798772 | AB44: 172.81861 | AC44: 47.297294 | AD44: 46.59794 | AE44: 48.316104 | AF44: 52.086466 | AG44: 194.29781 | AH44: 52.94 | AI44: 54.68 | AJ44: 56.69 | AK44: 57.36 | AL44: 221.67 | AM44: 57.29 | AN44: 57.628011 | AO44: 57.199092 | AP44: 59.57618 | AQ44: 231.69328 | AR44: 61.41073 | AS44: 62.007053 | AT44: 62.768312 | AU44: 66.90607 | AV44: 253.09216 | AW44: 67.066793 | AX44: 67.14843 | AY44: 65.754833 | AZ44: 69.085093 | BA44: 269.05515 | BB44: 68.794898 | BC44: 68.169777 | BD44: 68.88643 | BE44: 71.981461 | BF44: 277.83256 | BG44: 71.507166 | BH44: 71.107992 | BI44: 71.474731 | BJ44: 74.047748 | BK44: 288.13764 | BL44: 74.890556 | BM44: 73.458177 | BN44: 69.091277 | BO44: 71.578493 | BP44: 289.0185 | BQ44: 72.75762 | BR44: 73.038344 | BS44: 73.213705 | BT44: 78.535936 | BU44: 297.54561 | BV44: 80.240472 | BW44: 78.524811 | BX44: 78.711923 | BY44: 84.281717 | BZ44: 321.75892 | CA44: 86.4075 | CB44: 86.077325 | CC44: 85.805745 | CD44: 88.874564 | CE44: =SUM(CA44:CD44) -> 347.16513 | CF44: 89.107399 | CG44: 88.79184 | CH44: 89.872494 | CI44: 93.9418 | CJ44: =SUM(CF44:CI44) -> 361.71353 | CK44: 91.319916 | CL44: 93.292915 | CM44: 97.041531 | CN44: 101.75032 | CO44: =SUM(CK44:CN44) -> 383.40469
A45: E | B45: Pengadaan Air, Pengelolaan Sampah, Limbah dan Daur Ulang | D45: 21601.171 | E45: 22650.09 | F45: 22836.421 | G45: 23535.204 | H45: 90622.886 | I45: 23414.55 | J45: 23769.456 | K45: 23722.096 | L45: 23774.898 | M45: 94680.999 | N45: 24204.987 | O45: 24855.121 | P45: 25373.391 | Q45: 25933.661 | R45: 100367.16 | S45: 26111.021 | T45: 26557.112 | U45: 27317.183 | V45: 28194.872 | W45: 108180.19 | X45: 29049.65 | Y45: 29730.505 | Z45: 30376.755 | AA45: 29955.689 | AB45: 119112.6 | AC45: 30118.743 | AD45: 30767.159 | AE45: 32567.613 | AF45: 33519.494 | AG45: 126973.01 | AH45: 33936.74 | AI45: 34569.42 | AJ45: 35130.22 | AK45: 35873.94 | AL45: 139510.32 | AM45: 34935.404 | AN45: 36933.902 | AO45: 37386.483 | AP45: 37846.867 | AQ45: 147102.66 | AR45: 37684.956 | AS45: 39367.204 | AT45: 40274.796 | AU45: 41385.701 | AV45: 158712.66 | AW45: 39984.083 | AX45: 41265.67 | AY45: 43947.717 | AZ45: 44372.906 | BA45: 169570.38 | BB45: 42998.568 | BC45: 43813.947 | BD45: 44887.162 | BE45: 45340.758 | BF45: 177040.44 | BG45: 45213.717 | BH45: 46124.79 | BI45: 48076.142 | BJ45: 47885.644 | BK45: 187300.29 | BL45: 47750.334 | BM45: 47057.702 | BN45: 49463.398 | BO45: 47145.88 | BP45: 191417.31 | BQ45: 48825.139 | BR45: 50753.96 | BS45: 51117.762 | BT45: 52202.662 | BU45: 202899.52 | BV45: 50787.596 | BW45: 52414.524 | BX45: 52916.653 | BY45: 56658.013 | BZ45: 212776.79 | CA45: 56079.795 | CB45: 56764.639 | CC45: 57028.54 | CD45: 59110.811 | CE45: =SUM(CA45:CD45) -> 228983.78 | CF45: 58155.16 | CG45: 59183.905 | CH45: 59217.233 | CI45: 59960.889 | CJ45: =SUM(CF45:CI45) -> 236517.19 | CK45: 59659.416 | CL45: 60718.696 | CM45: 60597.148 | CN45: 61881.855 | CO45: =SUM(CK45:CN45) -> 242857.12
A46: F | B46: Konstruksi | D46: 131148.76 | E46: 133245.86 | F46: 148568.99 | G46: 158617.09 | H46: 571580.7 | I46: 169937.85 | J46: 176255.66 | K46: 184177.52 | L46: 198166.81 | M46: 728537.85 | N46: 261321.79 | O46: 294194.64 | P46: 313423.04 | Q46: 327085.5 | R46: 1196025 | S46: 328735.58 | T46: 349263.65 | U46: 372298.74 | V46: 401117.8 | W46: 1451415.8 | X46: 401935.01 | Y46: 423277.86 | Z46: 445521.94 | AA46: 455605.11 | AB46: 1726339.9 | AC46: 435057.56 | AD46: 494568.17 | AE46: 524825.79 | AF46: 562178.88 | AG46: 2016630.4 | AH46: 550721.47 | AI46: 572610.95 | AJ46: 602337.7 | AK46: 626436.57 | AL46: 2352106.7 | AM46: 608725.42 | AN46: 628018.37 | AO46: 667038.34 | AP46: 706656.41 | AQ46: 2610438.5 | AR46: 659411.47 | AS46: 695705.21 | AT46: 715503.94 | AU46: 739307.78 | AV46: 2809928.4 | AW46: 697947.05 | AX46: 724548.04 | AY46: 777061.66 | AZ46: 809035.74 | BA46: 3008592.5 | BB46: 771689.2 | BC46: 800861.12 | BD46: 844737.22 | BE46: 876369.14 | BF46: 3293656.7 | BG46: 848255.65 | BH46: 885356.56 | BI46: 921208.28 | BJ46: 946552.6 | BK46: 3601373.1 | BL46: 902218.11 | BM46: 906538.6 | BN46: 908496.78 | BO46: 915341.44 | BP46: 3632594.9 | BQ46: 917056.05 | BR46: 942078.33 | BS46: 992010.57 | BT46: 1019610 | BU46: 3870755 | BV46: 936169.98 | BW46: 1015564.6 | BX46: 1044089.9 | BY46: 1166788.7 | BZ46: 4162613.3 | CA46: 1079184.6 | CB46: 1090676.5 | CC46: 1165778.5 | CD46: 1207268.2 | CE46: =SUM(CA46:CD46) -> 4542907.9 | CF46: 1118686.5 | CG46: 1207225.6 | CH46: 1231400.8 | CI46: 1313437.2 | CJ46: =SUM(CF46:CI46) -> 4870750.1 | CK46: 1149637.8 | CL46: 1294754.6 | CM46: 1326872.3 | CN46: 1389239.4 | CO46: =SUM(CK46:CN46) -> 5160504.1
...

Sheet 11 KabKot
A1: TABEL 1. PDRB SERI 2010 ATAS DASAR HARGA BERLAKU MENURUT LAPANGAN USAHA (JUTA RUPIAH)
A2: Propinsi | B2: : | C2: Maluku | D2: Kabupaten/Kota : | E2: 11 Kab/Kota | CG2: =CF9 -> #REF! | CH2: =CG2/CF83*100 -> #REF!
CH3: =CH2/CD453*100-100 -> #REF!
A4: Kategori | B4: Uraian | D4: 2008 | I4: =D4+1 -> 2009 | N4: =I4+1 -> 2010 | S4: =N4+1 -> 2011 | X4: =S4+1 -> 2012 | AC4: =X4+1 -> 2013 | AH4: =AC4+1 -> 2014 | AM4: =AH4+1 -> 2015 | AR4: =AM4+1 -> 2016 | AW4: =AR4+1 -> 2017 | BB4: =AW4+1 -> 2018 | BG4: =BB4+1 -> 2019 | BL4: =BG4+1 -> 2020 | BQ4: =BL4+1 -> 2021 | BV4: =BQ4+1 -> 2022 | CA4: =BV4+1 -> 2023 | CF4: =CA4+1 -> 2024 | CK4: =CF4+1 -> 2025
